2023-02-24 14:05:32,688 INFO: Microblog startup [in /Users/pauldobrowsky/Projects/microblog/app/__init__.py:44]
2023-02-24 14:06:39,659 ERROR: Exception on /edit_profile [POST] [in /Users/pauldobrowsky/Projects/microblog/venv/lib/python3.9/site-packages/flask/app.py:1741]
Traceback (most recent call last):
  File "/Users/pauldobrowsky/Projects/microblog/venv/lib/python3.9/site-packages/sqlalchemy/engine/base.py", line 1964, in _exec_single_context
    self.dialect.do_execute(
  File "/Users/pauldobrowsky/Projects/microblog/venv/lib/python3.9/site-packages/sqlalchemy/engine/default.py", line 747, in do_execute
    cursor.execute(statement, parameters)
sqlite3.IntegrityError: UNIQUE constraint failed: user.username

The above exception was the direct cause of the following exception:

Traceback (most recent call last):
  File "/Users/pauldobrowsky/Projects/microblog/venv/lib/python3.9/site-packages/flask/app.py", line 2525, in wsgi_app
    response = self.full_dispatch_request()
  File "/Users/pauldobrowsky/Projects/microblog/venv/lib/python3.9/site-packages/flask/app.py", line 1822, in full_dispatch_request
    rv = self.handle_user_exception(e)
  File "/Users/pauldobrowsky/Projects/microblog/venv/lib/python3.9/site-packages/flask/app.py", line 1820, in full_dispatch_request
    rv = self.dispatch_request()
  File "/Users/pauldobrowsky/Projects/microblog/venv/lib/python3.9/site-packages/flask/app.py", line 1796, in dispatch_request
    return self.ensure_sync(self.view_functions[rule.endpoint])(**view_args)
  File "/Users/pauldobrowsky/Projects/microblog/venv/lib/python3.9/site-packages/flask_login/utils.py", line 290, in decorated_view
    return current_app.ensure_sync(func)(*args, **kwargs)
  File "/Users/pauldobrowsky/Projects/microblog/app/routes.py", line 99, in edit_profile
    db.session.commit()
  File "/Users/pauldobrowsky/Projects/microblog/venv/lib/python3.9/site-packages/sqlalchemy/orm/scoping.py", line 538, in commit
    return self._proxied.commit()
  File "/Users/pauldobrowsky/Projects/microblog/venv/lib/python3.9/site-packages/sqlalchemy/orm/session.py", line 1903, in commit
    trans.commit(_to_root=True)
  File "<string>", line 2, in commit
  File "/Users/pauldobrowsky/Projects/microblog/venv/lib/python3.9/site-packages/sqlalchemy/orm/state_changes.py", line 137, in _go
    ret_value = fn(self, *arg, **kw)
  File "/Users/pauldobrowsky/Projects/microblog/venv/lib/python3.9/site-packages/sqlalchemy/orm/session.py", line 1218, in commit
    self._prepare_impl()
  File "<string>", line 2, in _prepare_impl
  File "/Users/pauldobrowsky/Projects/microblog/venv/lib/python3.9/site-packages/sqlalchemy/orm/state_changes.py", line 137, in _go
    ret_value = fn(self, *arg, **kw)
  File "/Users/pauldobrowsky/Projects/microblog/venv/lib/python3.9/site-packages/sqlalchemy/orm/session.py", line 1193, in _prepare_impl
    self.session.flush()
  File "/Users/pauldobrowsky/Projects/microblog/venv/lib/python3.9/site-packages/sqlalchemy/orm/session.py", line 4153, in flush
    self._flush(objects)
  File "/Users/pauldobrowsky/Projects/microblog/venv/lib/python3.9/site-packages/sqlalchemy/orm/session.py", line 4290, in _flush
    transaction.rollback(_capture_exception=True)
  File "/Users/pauldobrowsky/Projects/microblog/venv/lib/python3.9/site-packages/sqlalchemy/util/langhelpers.py", line 147, in __exit__
    raise exc_value.with_traceback(exc_tb)
  File "/Users/pauldobrowsky/Projects/microblog/venv/lib/python3.9/site-packages/sqlalchemy/orm/session.py", line 4250, in _flush
    flush_context.execute()
  File "/Users/pauldobrowsky/Projects/microblog/venv/lib/python3.9/site-packages/sqlalchemy/orm/unitofwork.py", line 467, in execute
    rec.execute(self)
  File "/Users/pauldobrowsky/Projects/microblog/venv/lib/python3.9/site-packages/sqlalchemy/orm/unitofwork.py", line 644, in execute
    util.preloaded.orm_persistence.save_obj(
  File "/Users/pauldobrowsky/Projects/microblog/venv/lib/python3.9/site-packages/sqlalchemy/orm/persistence.py", line 85, in save_obj
    _emit_update_statements(
  File "/Users/pauldobrowsky/Projects/microblog/venv/lib/python3.9/site-packages/sqlalchemy/orm/persistence.py", line 894, in _emit_update_statements
    c = connection.execute(
  File "/Users/pauldobrowsky/Projects/microblog/venv/lib/python3.9/site-packages/sqlalchemy/engine/base.py", line 1414, in execute
    return meth(
  File "/Users/pauldobrowsky/Projects/microblog/venv/lib/python3.9/site-packages/sqlalchemy/sql/elements.py", line 485, in _execute_on_connection
    return connection._execute_clauseelement(
  File "/Users/pauldobrowsky/Projects/microblog/venv/lib/python3.9/site-packages/sqlalchemy/engine/base.py", line 1638, in _execute_clauseelement
    ret = self._execute_context(
  File "/Users/pauldobrowsky/Projects/microblog/venv/lib/python3.9/site-packages/sqlalchemy/engine/base.py", line 1842, in _execute_context
    return self._exec_single_context(
  File "/Users/pauldobrowsky/Projects/microblog/venv/lib/python3.9/site-packages/sqlalchemy/engine/base.py", line 1983, in _exec_single_context
    self._handle_dbapi_exception(
  File "/Users/pauldobrowsky/Projects/microblog/venv/lib/python3.9/site-packages/sqlalchemy/engine/base.py", line 2325, in _handle_dbapi_exception
    raise sqlalchemy_exception.with_traceback(exc_info[2]) from e
  File "/Users/pauldobrowsky/Projects/microblog/venv/lib/python3.9/site-packages/sqlalchemy/engine/base.py", line 1964, in _exec_single_context
    self.dialect.do_execute(
  File "/Users/pauldobrowsky/Projects/microblog/venv/lib/python3.9/site-packages/sqlalchemy/engine/default.py", line 747, in do_execute
    cursor.execute(statement, parameters)
sqlalchemy.exc.IntegrityError: (sqlite3.IntegrityError) UNIQUE constraint failed: user.username
[SQL: UPDATE user SET username=?, about_me=? WHERE user.id = ?]
[parameters: ('Paul', 'I am a fake user', 2)]
(Background on this error at: https://sqlalche.me/e/20/gkpj)
2023-02-24 14:32:33,549 INFO: Microblog startup [in /Users/pauldobrowsky/Projects/microblog/app/__init__.py:44]
2023-02-24 14:32:54,930 INFO: Microblog startup [in /Users/pauldobrowsky/Projects/microblog/app/__init__.py:44]
2023-02-24 14:34:36,289 INFO: Microblog startup [in /Users/pauldobrowsky/Projects/microblog/app/__init__.py:44]
2023-02-24 16:51:24,053 INFO: Microblog startup [in /Users/pauldobrowsky/Projects/microblog/app/__init__.py:44]
2023-02-24 16:51:53,160 ERROR: Exception on /user/test [GET] [in /Users/pauldobrowsky/Projects/microblog/venv/lib/python3.9/site-packages/flask/app.py:1741]
Traceback (most recent call last):
  File "/Users/pauldobrowsky/Projects/microblog/venv/lib/python3.9/site-packages/flask/app.py", line 2525, in wsgi_app
    response = self.full_dispatch_request()
  File "/Users/pauldobrowsky/Projects/microblog/venv/lib/python3.9/site-packages/flask/app.py", line 1822, in full_dispatch_request
    rv = self.handle_user_exception(e)
  File "/Users/pauldobrowsky/Projects/microblog/venv/lib/python3.9/site-packages/flask/app.py", line 1820, in full_dispatch_request
    rv = self.dispatch_request()
  File "/Users/pauldobrowsky/Projects/microblog/venv/lib/python3.9/site-packages/flask/app.py", line 1796, in dispatch_request
    return self.ensure_sync(self.view_functions[rule.endpoint])(**view_args)
  File "/Users/pauldobrowsky/Projects/microblog/venv/lib/python3.9/site-packages/flask_login/utils.py", line 290, in decorated_view
    return current_app.ensure_sync(func)(*args, **kwargs)
  File "/Users/pauldobrowsky/Projects/microblog/app/routes.py", line 89, in user
    return render_template('user.html', user=user, posts=posts)
  File "/Users/pauldobrowsky/Projects/microblog/venv/lib/python3.9/site-packages/flask/templating.py", line 147, in render_template
    return _render(app, template, context)
  File "/Users/pauldobrowsky/Projects/microblog/venv/lib/python3.9/site-packages/flask/templating.py", line 130, in _render
    rv = template.render(context)
  File "/Users/pauldobrowsky/Projects/microblog/venv/lib/python3.9/site-packages/jinja2/environment.py", line 1301, in render
    self.environment.handle_exception()
  File "/Users/pauldobrowsky/Projects/microblog/venv/lib/python3.9/site-packages/jinja2/environment.py", line 936, in handle_exception
    raise rewrite_traceback_stack(source=source)
  File "/Users/pauldobrowsky/Projects/microblog/app/templates/user.html", line 1, in top-level template code
    {% extends "base.html" %}
  File "/Users/pauldobrowsky/Projects/microblog/app/templates/base.html", line 30, in top-level template code
    {% block content %}{% endblock %}
  File "/Users/pauldobrowsky/Projects/microblog/app/templates/user.html", line 15, in block 'content'
    {% elif not current_user.isfollowing(user) %}
  File "/Users/pauldobrowsky/Projects/microblog/venv/lib/python3.9/site-packages/jinja2/utils.py", line 83, in from_obj
    if hasattr(obj, "jinja_pass_arg"):
jinja2.exceptions.UndefinedError: 'app.models.User object' has no attribute 'isfollowing'
2023-02-24 16:52:22,861 INFO: Microblog startup [in /Users/pauldobrowsky/Projects/microblog/app/__init__.py:44]
2023-02-25 10:57:06,137 INFO: Microblog startup [in /Users/pauldobrowsky/Projects/microblog/app/__init__.py:44]
2023-02-25 11:15:29,130 INFO: Microblog startup [in /Users/pauldobrowsky/Projects/microblog/app/__init__.py:44]
